```python
FLASK_APP = app.py
FLASK_ENV = development
FLASK_DEBUG = 0
In folder /Users/huangjiabao/GitHub/Github_Repo/FeedVault
/Users/huangjiabao/GitHub/Github_Repo/FeedVault/.venv/bin/python -m flask run 
 * Serving Flask app 'app.py'
 * Debug mode: off
WARNING: This is a development server. Do not use it in a production deployment. Use a production WSGI server instead.
 * Running on http://127.0.0.1:5000
Press CTRL+C to quit
127.0.0.1 - - [08/Nov/2024 20:14:46] "GET / HTTP/1.1" 404 -
[2024-11-08 20:14:55,929] ERROR in app: Exception on /admin [GET]
Traceback (most recent call last):
  File "/Users/huangjiabao/GitHub/Github_Repo/FeedVault/.venv/lib/python3.9/site-packages/sqlalchemy/engine/base.py", line 1967, in _exec_single_context
    self.dialect.do_execute(
  File "/Users/huangjiabao/GitHub/Github_Repo/FeedVault/.venv/lib/python3.9/site-packages/sqlalchemy/engine/default.py", line 941, in do_execute
    cursor.execute(statement, parameters)
sqlite3.OperationalError: no such table: user

The above exception was the direct cause of the following exception:

Traceback (most recent call last):
  File "/Users/huangjiabao/GitHub/Github_Repo/FeedVault/.venv/lib/python3.9/site-packages/flask/app.py", line 1473, in wsgi_app
    response = self.full_dispatch_request()
  File "/Users/huangjiabao/GitHub/Github_Repo/FeedVault/.venv/lib/python3.9/site-packages/flask/app.py", line 882, in full_dispatch_request
    rv = self.handle_user_exception(e)
  File "/Users/huangjiabao/GitHub/Github_Repo/FeedVault/.venv/lib/python3.9/site-packages/flask/app.py", line 880, in full_dispatch_request
    rv = self.dispatch_request()
  File "/Users/huangjiabao/GitHub/Github_Repo/FeedVault/.venv/lib/python3.9/site-packages/flask/app.py", line 865, in dispatch_request
    return self.ensure_sync(self.view_functions[rule.endpoint])(**view_args)  # type: ignore[no-any-return]
  File "/Users/huangjiabao/GitHub/Github_Repo/FeedVault/app.py", line 56, in admin
    users = User.query.all()
  File "/Users/huangjiabao/GitHub/Github_Repo/FeedVault/.venv/lib/python3.9/site-packages/sqlalchemy/orm/query.py", line 2673, in all
    return self._iter().all()  # type: ignore
  File "/Users/huangjiabao/GitHub/Github_Repo/FeedVault/.venv/lib/python3.9/site-packages/sqlalchemy/orm/query.py", line 2827, in _iter
    result: Union[ScalarResult[_T], Result[_T]] = self.session.execute(
  File "/Users/huangjiabao/GitHub/Github_Repo/FeedVault/.venv/lib/python3.9/site-packages/sqlalchemy/orm/session.py", line 2362, in execute
    return self._execute_internal(
  File "/Users/huangjiabao/GitHub/Github_Repo/FeedVault/.venv/lib/python3.9/site-packages/sqlalchemy/orm/session.py", line 2247, in _execute_internal
    result: Result[Any] = compile_state_cls.orm_execute_statement(
  File "/Users/huangjiabao/GitHub/Github_Repo/FeedVault/.venv/lib/python3.9/site-packages/sqlalchemy/orm/context.py", line 305, in orm_execute_statement
    result = conn.execute(
  File "/Users/huangjiabao/GitHub/Github_Repo/FeedVault/.venv/lib/python3.9/site-packages/sqlalchemy/engine/base.py", line 1418, in execute
    return meth(
  File "/Users/huangjiabao/GitHub/Github_Repo/FeedVault/.venv/lib/python3.9/site-packages/sqlalchemy/sql/elements.py", line 515, in _execute_on_connection
    return connection._execute_clauseelement(
  File "/Users/huangjiabao/GitHub/Github_Repo/FeedVault/.venv/lib/python3.9/site-packages/sqlalchemy/engine/base.py", line 1640, in _execute_clauseelement
    ret = self._execute_context(
  File "/Users/huangjiabao/GitHub/Github_Repo/FeedVault/.venv/lib/python3.9/site-packages/sqlalchemy/engine/base.py", line 1846, in _execute_context
    return self._exec_single_context(
  File "/Users/huangjiabao/GitHub/Github_Repo/FeedVault/.venv/lib/python3.9/site-packages/sqlalchemy/engine/base.py", line 1986, in _exec_single_context
    self._handle_dbapi_exception(
  File "/Users/huangjiabao/GitHub/Github_Repo/FeedVault/.venv/lib/python3.9/site-packages/sqlalchemy/engine/base.py", line 2355, in _handle_dbapi_exception
    raise sqlalchemy_exception.with_traceback(exc_info[2]) from e
  File "/Users/huangjiabao/GitHub/Github_Repo/FeedVault/.venv/lib/python3.9/site-packages/sqlalchemy/engine/base.py", line 1967, in _exec_single_context
    self.dialect.do_execute(
  File "/Users/huangjiabao/GitHub/Github_Repo/FeedVault/.venv/lib/python3.9/site-packages/sqlalchemy/engine/default.py", line 941, in do_execute
    cursor.execute(statement, parameters)
sqlalchemy.exc.OperationalError: (sqlite3.OperationalError) no such table: user
[SQL: SELECT user.id AS user_id, user.username AS user_username, user.password AS user_password, user.expiration_date AS user_expiration_date, user.subscription_link AS user_subscription_link 
FROM user]
(Background on this error at: https://sqlalche.me/e/20/e3q8)
127.0.0.1 - - [08/Nov/2024 20:14:55] "GET /admin HTTP/1.1" 500 -
```

这个错误提示 `no such table: user` 表示数据库中缺少 `user` 表。这个通常发生在首次运行代码时，数据库和数据表尚未初始化。可以按照以下步骤解决这个问题：

1. **确保数据库创建**：在 Flask 应用启动时添加数据库的创建代码。你已经有 `db.create_all()` 的调用，但它可能没有执行成功。你可以尝试将它放在代码的开始部分，并直接运行一次来创建数据库和表。

2. **运行数据库迁移命令**：在终端中运行以下命令来创建数据库和表结构。

### 步骤 1：在启动 Flask 时创建数据库

首先确保 `db.create_all()` 在应用启动时执行，如下所示：

```python
if __name__ == '__main__':
    with app.app_context():
        db.create_all()  # 创建数据库和表
    app.run(debug=True)
```

然后，再次运行应用，`db.create_all()` 应该会创建 `user` 表。

### 步骤 2：手动运行数据库迁移命令

如果上述步骤无法解决问题，你可以尝试以下命令（在 Flask 项目根目录下运行）来手动创建数据库表：

```bash
python -m flask shell
```

然后在进入 Flask shell 后，运行：

```python
from app import db
db.create_all()
```

这应该会创建数据库表。

### 再次运行应用

现在可以退出 shell，并再次运行应用：

```bash
python app.py
```

访问 `http://127.0.0.1:5000/admin`，检查是否成功创建了 `user` 表并正常加载页面。